{
 "cells": [
  {
   "cell_type": "code",
   "execution_count": 1,
   "metadata": {},
   "outputs": [],
   "source": [
    "from forward import solve_forward\n",
    "from simulation import Simulation"
   ]
  },
  {
   "cell_type": "markdown",
   "metadata": {},
   "source": [
    "### Solve Forward"
   ]
  },
  {
   "cell_type": "code",
   "execution_count": 2,
   "metadata": {},
   "outputs": [
    {
     "name": "stdout",
     "output_type": "stream",
     "text": [
      "Forward problem is solved.\n",
      "Electrodes: (73, 3)\n",
      "Dipoles: (50460, 3)\n",
      "Leadfield: (73, 50460)\n"
     ]
    }
   ],
   "source": [
    "fwd = solve_forward()"
   ]
  },
  {
   "cell_type": "markdown",
   "metadata": {},
   "source": [
    "### Simulation"
   ]
  },
  {
   "cell_type": "code",
   "execution_count": 3,
   "metadata": {},
   "outputs": [
    {
     "name": "stdout",
     "output_type": "stream",
     "text": [
      "Simulate Sources.\n"
     ]
    },
    {
     "name": "stderr",
     "output_type": "stream",
     "text": [
      "100%|██████████| 100/100 [00:02<00:00, 42.48it/s]"
     ]
    },
    {
     "name": "stdout",
     "output_type": "stream",
     "text": [
      "Simulate EEG.\n",
      "Project sources to EEG.\n"
     ]
    },
    {
     "name": "stderr",
     "output_type": "stream",
     "text": [
      "\n"
     ]
    }
   ],
   "source": [
    "sim = Simulation(fwd=fwd)\n",
    "\n",
    "sim.simulate(n_samples=100)"
   ]
  },
  {
   "cell_type": "code",
   "execution_count": null,
   "metadata": {},
   "outputs": [],
   "source": [
    "print('EGG:',sim.eeg_data.shape)\n",
    "print('Sources:',sim.source_data.shape)"
   ]
  },
  {
   "cell_type": "code",
   "execution_count": null,
   "metadata": {},
   "outputs": [],
   "source": [
    "import numpy as np\n",
    "np.save('./matlab/data/eeg_sim',sim.eeg_data)"
   ]
  },
  {
   "cell_type": "code",
   "execution_count": 4,
   "metadata": {},
   "outputs": [
    {
     "name": "stderr",
     "output_type": "stream",
     "text": [
      "2021-11-30 23:59:15.569757: W tensorflow/stream_executor/platform/default/dso_loader.cc:64] Could not load dynamic library 'libcudart.so.11.0'; dlerror: libcudart.so.11.0: cannot open shared object file: No such file or directory\n",
      "2021-11-30 23:59:15.569777: I tensorflow/stream_executor/cuda/cudart_stub.cc:29] Ignore above cudart dlerror if you do not have a GPU set up on your machine.\n"
     ]
    }
   ],
   "source": [
    "from net import EEGNet\n",
    "\n",
    "eegnet = EEGNet(fwd=fwd,sim=sim)"
   ]
  },
  {
   "cell_type": "code",
   "execution_count": 5,
   "metadata": {},
   "outputs": [
    {
     "name": "stdout",
     "output_type": "stream",
     "text": [
      "Model: \"sequential\"\n",
      "_________________________________________________________________\n",
      " Layer (type)                Output Shape              Param #   \n",
      "=================================================================\n",
      " dense (Dense)               (None, 100)               7400      \n",
      "                                                                 \n",
      " dense_1 (Dense)             (None, 50460)             5096460   \n",
      "                                                                 \n",
      "=================================================================\n",
      "Total params: 5,103,860\n",
      "Trainable params: 5,103,860\n",
      "Non-trainable params: 0\n",
      "_________________________________________________________________\n"
     ]
    },
    {
     "name": "stderr",
     "output_type": "stream",
     "text": [
      "2021-11-30 23:59:18.223301: W tensorflow/stream_executor/platform/default/dso_loader.cc:64] Could not load dynamic library 'libcuda.so.1'; dlerror: libcuda.so.1: cannot open shared object file: No such file or directory\n",
      "2021-11-30 23:59:18.223335: W tensorflow/stream_executor/cuda/cuda_driver.cc:269] failed call to cuInit: UNKNOWN ERROR (303)\n",
      "2021-11-30 23:59:18.223379: I tensorflow/stream_executor/cuda/cuda_diagnostics.cc:156] kernel driver does not appear to be running on this host (thanos): /proc/driver/nvidia/version does not exist\n",
      "2021-11-30 23:59:18.223724: I tensorflow/core/platform/cpu_feature_guard.cc:151] This TensorFlow binary is optimized with oneAPI Deep Neural Network Library (oneDNN) to use the following CPU instructions in performance-critical operations:  AVX2 FMA\n",
      "To enable them in other operations, rebuild TensorFlow with the appropriate compiler flags.\n"
     ]
    }
   ],
   "source": [
    "eegnet.build_model()"
   ]
  },
  {
   "cell_type": "code",
   "execution_count": 6,
   "metadata": {},
   "outputs": [
    {
     "name": "stdout",
     "output_type": "stream",
     "text": [
      "Epoch 1/50\n"
     ]
    },
    {
     "ename": "ValueError",
     "evalue": "in user code:\n\n    File \"/home/thanos/Documents/thesis/env/lib/python3.8/site-packages/keras/engine/training.py\", line 878, in train_function  *\n        return step_function(self, iterator)\n    File \"/home/thanos/Documents/thesis/env/lib/python3.8/site-packages/keras/engine/training.py\", line 867, in step_function  **\n        outputs = model.distribute_strategy.run(run_step, args=(data,))\n    File \"/home/thanos/Documents/thesis/env/lib/python3.8/site-packages/keras/engine/training.py\", line 860, in run_step  **\n        outputs = model.train_step(data)\n    File \"/home/thanos/Documents/thesis/env/lib/python3.8/site-packages/keras/engine/training.py\", line 808, in train_step\n        y_pred = self(x, training=True)\n    File \"/home/thanos/Documents/thesis/env/lib/python3.8/site-packages/keras/utils/traceback_utils.py\", line 67, in error_handler\n        raise e.with_traceback(filtered_tb) from None\n    File \"/home/thanos/Documents/thesis/env/lib/python3.8/site-packages/keras/engine/input_spec.py\", line 247, in assert_input_compatibility\n        raise ValueError(\n\n    ValueError: Exception encountered when calling layer \"sequential\" (type Sequential).\n    \n    Input 0 of layer \"dense\" is incompatible with the layer: expected axis -1of input shape to have value 73, but received input with shape (None, 100)\n    \n    Call arguments received:\n      • inputs=tf.Tensor(shape=(None, 100), dtype=float32)\n      • training=True\n      • mask=None\n",
     "output_type": "error",
     "traceback": [
      "\u001b[0;31m---------------------------------------------------------------------------\u001b[0m",
      "\u001b[0;31mValueError\u001b[0m                                Traceback (most recent call last)",
      "\u001b[0;32m/tmp/ipykernel_67202/3606008081.py\u001b[0m in \u001b[0;36m<module>\u001b[0;34m\u001b[0m\n\u001b[0;32m----> 1\u001b[0;31m \u001b[0meegnet\u001b[0m\u001b[0;34m.\u001b[0m\u001b[0mfit\u001b[0m\u001b[0;34m(\u001b[0m\u001b[0;34m)\u001b[0m\u001b[0;34m\u001b[0m\u001b[0;34m\u001b[0m\u001b[0m\n\u001b[0m",
      "\u001b[0;32m~/Documents/thesis/net.py\u001b[0m in \u001b[0;36mfit\u001b[0;34m(self, learning_rate, validation_split, epochs, metrics, false_positive_penalty, delta, batch_size, loss, patience)\u001b[0m\n\u001b[1;32m    142\u001b[0m         \u001b[0mcallbacks\u001b[0m \u001b[0;34m=\u001b[0m \u001b[0;34m[\u001b[0m\u001b[0mes\u001b[0m\u001b[0;34m]\u001b[0m\u001b[0;34m\u001b[0m\u001b[0;34m\u001b[0m\u001b[0m\n\u001b[1;32m    143\u001b[0m \u001b[0;34m\u001b[0m\u001b[0m\n\u001b[0;32m--> 144\u001b[0;31m         self.model.fit(x, y, \n\u001b[0m\u001b[1;32m    145\u001b[0m                 \u001b[0mepochs\u001b[0m\u001b[0;34m=\u001b[0m\u001b[0mepochs\u001b[0m\u001b[0;34m,\u001b[0m \u001b[0mbatch_size\u001b[0m\u001b[0;34m=\u001b[0m\u001b[0mbatch_size\u001b[0m\u001b[0;34m,\u001b[0m \u001b[0mshuffle\u001b[0m\u001b[0;34m=\u001b[0m\u001b[0;32mTrue\u001b[0m\u001b[0;34m,\u001b[0m\u001b[0;34m\u001b[0m\u001b[0;34m\u001b[0m\u001b[0m\n\u001b[1;32m    146\u001b[0m                 validation_split=validation_split, callbacks=callbacks)\n",
      "\u001b[0;32m~/Documents/thesis/env/lib/python3.8/site-packages/keras/utils/traceback_utils.py\u001b[0m in \u001b[0;36merror_handler\u001b[0;34m(*args, **kwargs)\u001b[0m\n\u001b[1;32m     65\u001b[0m     \u001b[0;32mexcept\u001b[0m \u001b[0mException\u001b[0m \u001b[0;32mas\u001b[0m \u001b[0me\u001b[0m\u001b[0;34m:\u001b[0m  \u001b[0;31m# pylint: disable=broad-except\u001b[0m\u001b[0;34m\u001b[0m\u001b[0;34m\u001b[0m\u001b[0m\n\u001b[1;32m     66\u001b[0m       \u001b[0mfiltered_tb\u001b[0m \u001b[0;34m=\u001b[0m \u001b[0m_process_traceback_frames\u001b[0m\u001b[0;34m(\u001b[0m\u001b[0me\u001b[0m\u001b[0;34m.\u001b[0m\u001b[0m__traceback__\u001b[0m\u001b[0;34m)\u001b[0m\u001b[0;34m\u001b[0m\u001b[0;34m\u001b[0m\u001b[0m\n\u001b[0;32m---> 67\u001b[0;31m       \u001b[0;32mraise\u001b[0m \u001b[0me\u001b[0m\u001b[0;34m.\u001b[0m\u001b[0mwith_traceback\u001b[0m\u001b[0;34m(\u001b[0m\u001b[0mfiltered_tb\u001b[0m\u001b[0;34m)\u001b[0m \u001b[0;32mfrom\u001b[0m \u001b[0;32mNone\u001b[0m\u001b[0;34m\u001b[0m\u001b[0;34m\u001b[0m\u001b[0m\n\u001b[0m\u001b[1;32m     68\u001b[0m     \u001b[0;32mfinally\u001b[0m\u001b[0;34m:\u001b[0m\u001b[0;34m\u001b[0m\u001b[0;34m\u001b[0m\u001b[0m\n\u001b[1;32m     69\u001b[0m       \u001b[0;32mdel\u001b[0m \u001b[0mfiltered_tb\u001b[0m\u001b[0;34m\u001b[0m\u001b[0;34m\u001b[0m\u001b[0m\n",
      "\u001b[0;32m~/Documents/thesis/env/lib/python3.8/site-packages/tensorflow/python/framework/func_graph.py\u001b[0m in \u001b[0;36mautograph_handler\u001b[0;34m(*args, **kwargs)\u001b[0m\n\u001b[1;32m   1127\u001b[0m           \u001b[0;32mexcept\u001b[0m \u001b[0mException\u001b[0m \u001b[0;32mas\u001b[0m \u001b[0me\u001b[0m\u001b[0;34m:\u001b[0m  \u001b[0;31m# pylint:disable=broad-except\u001b[0m\u001b[0;34m\u001b[0m\u001b[0;34m\u001b[0m\u001b[0m\n\u001b[1;32m   1128\u001b[0m             \u001b[0;32mif\u001b[0m \u001b[0mhasattr\u001b[0m\u001b[0;34m(\u001b[0m\u001b[0me\u001b[0m\u001b[0;34m,\u001b[0m \u001b[0;34m\"ag_error_metadata\"\u001b[0m\u001b[0;34m)\u001b[0m\u001b[0;34m:\u001b[0m\u001b[0;34m\u001b[0m\u001b[0;34m\u001b[0m\u001b[0m\n\u001b[0;32m-> 1129\u001b[0;31m               \u001b[0;32mraise\u001b[0m \u001b[0me\u001b[0m\u001b[0;34m.\u001b[0m\u001b[0mag_error_metadata\u001b[0m\u001b[0;34m.\u001b[0m\u001b[0mto_exception\u001b[0m\u001b[0;34m(\u001b[0m\u001b[0me\u001b[0m\u001b[0;34m)\u001b[0m\u001b[0;34m\u001b[0m\u001b[0;34m\u001b[0m\u001b[0m\n\u001b[0m\u001b[1;32m   1130\u001b[0m             \u001b[0;32melse\u001b[0m\u001b[0;34m:\u001b[0m\u001b[0;34m\u001b[0m\u001b[0;34m\u001b[0m\u001b[0m\n\u001b[1;32m   1131\u001b[0m               \u001b[0;32mraise\u001b[0m\u001b[0;34m\u001b[0m\u001b[0;34m\u001b[0m\u001b[0m\n",
      "\u001b[0;31mValueError\u001b[0m: in user code:\n\n    File \"/home/thanos/Documents/thesis/env/lib/python3.8/site-packages/keras/engine/training.py\", line 878, in train_function  *\n        return step_function(self, iterator)\n    File \"/home/thanos/Documents/thesis/env/lib/python3.8/site-packages/keras/engine/training.py\", line 867, in step_function  **\n        outputs = model.distribute_strategy.run(run_step, args=(data,))\n    File \"/home/thanos/Documents/thesis/env/lib/python3.8/site-packages/keras/engine/training.py\", line 860, in run_step  **\n        outputs = model.train_step(data)\n    File \"/home/thanos/Documents/thesis/env/lib/python3.8/site-packages/keras/engine/training.py\", line 808, in train_step\n        y_pred = self(x, training=True)\n    File \"/home/thanos/Documents/thesis/env/lib/python3.8/site-packages/keras/utils/traceback_utils.py\", line 67, in error_handler\n        raise e.with_traceback(filtered_tb) from None\n    File \"/home/thanos/Documents/thesis/env/lib/python3.8/site-packages/keras/engine/input_spec.py\", line 247, in assert_input_compatibility\n        raise ValueError(\n\n    ValueError: Exception encountered when calling layer \"sequential\" (type Sequential).\n    \n    Input 0 of layer \"dense\" is incompatible with the layer: expected axis -1of input shape to have value 73, but received input with shape (None, 100)\n    \n    Call arguments received:\n      • inputs=tf.Tensor(shape=(None, 100), dtype=float32)\n      • training=True\n      • mask=None\n"
     ]
    }
   ],
   "source": [
    "eegnet.fit()"
   ]
  }
 ],
 "metadata": {
  "interpreter": {
   "hash": "1ae971a6462940be47933e1f07228cb732a4a5829590a0ee471006fa906ff195"
  },
  "kernelspec": {
   "display_name": "Python 3.8.10 64-bit ('env': venv)",
   "language": "python",
   "name": "python3"
  },
  "language_info": {
   "codemirror_mode": {
    "name": "ipython",
    "version": 3
   },
   "file_extension": ".py",
   "mimetype": "text/x-python",
   "name": "python",
   "nbconvert_exporter": "python",
   "pygments_lexer": "ipython3",
   "version": "3.8.10"
  },
  "orig_nbformat": 4
 },
 "nbformat": 4,
 "nbformat_minor": 2
}
